Workbook

Sheet Cpte résultat
A1: ASSOCIATION - LES AMIS DE SOCRATE
A2: COMPTE DE RESULTAT 2023
A4: CHARGES | B4: Budget 2023 | C4: CR 2023 | E4: PRODUITS | F4: Budget 2023 | G4: CR 2023
A5: 60. Achats | B5: =SUM(B6:B9) -> 1546 | C5: =SUM(C6:C9) -> 4371.86 | E5: 70. Ventes de prod. fabriqués, prest. services, marchandises | F5: =SUM(F6:F7) -> 0 | G5: =SUM(G6:G7) -> 3277.24
A6: 602. Achats stockés – Autres approvisionnements (Banquet d'Ordre) | B6: 480 | C6: =Charges!B5 -> 3855 | E6: 701. Billeterie BO membres | G6: =+Produits!B5 -> 0
A7: 6063. Fournitures d’entr.et de petit équipement. | B7: 1066 | C7: =Charges!B6 -> 516.86 | E7: 701. Billeterie BO visiteurs | G7: =+Produits!B6 -> 3277.24
A8: 6064. Fournitures admin. | C8: =Charges!B7 -> 0 | E8: 71. Production stockée | F8: 0 | G8: 0
A9: 6068. Autres matières et fournitures. | C9: =Charges!B8 -> 0 | E9: 72. Production immobilisée | F9: 0 | G9: 0
A10: 61. Services extérieurs | B10: =SUM(B11:B15) -> 2035 | C10: =SUM(C11:C14) -> 1600 | E10: 74. Subventions d'exploitation | F10: 2100 | G10: 0
A11: 613. Locations | E11: 75. Autres produits de gestion courante | F11: =SUM(F12:F14) -> 2796 | G11: =SUM(G12:G14) -> 7225.3
A12: 6132. Locations immobilières fixe | C12: =+Charges!B20 -> 0 | E12: 756. Cotisations
A13: 6132. Locations immobilières variables Mousson | B13: 2000 | C13: =+Charges!B21 -> 1500 | E13: 7561. Cotisations membres | F13: 2796 | G13: =Produits!B12 -> 7225.3
A14: 6132. Locations immobilières variables (Fête familiale) | C14: =+Charges!B22 -> 100 | E14: 758. Produits divers de gestion courante
A15: 616. Primes d'assurances | B15: 35 | E15: 76. Produits financiers | F15: =SUM(F16) -> 0 | G15: =SUM(G16) -> 0
A16: 62. Autres services extérieurs | B16: =SUM(B17:B27) -> 715 | C16: =SUM(C17:C27) -> 5087.95 | E16: 768. Autres produits financiers. | G16: =Produits!B15 -> 0
A17: 6251. Voyages et déplacements (Convent, Congrès régional) | B17: 500 | C17: =+Charges!B32 -> 431.4 | E17: 77. Produits exceptionnels | F17: =SUM(F18:F18) -> 0 | G17: =SUM(G18:G18) -> 0
A18: 626. Frais postaux et de télécommunications | E18: 77181. Autres prod. except. sur op. de gestion | G18: =Produits!B17 -> 0
A19: 6261. Affranchissements | B19: 10 | C19: =+Charges!B34 -> 0 | E19: 77185. Remboursement trop perçu | G19: =Produits!B18 -> 30
A20: 6262. Abonnement Mailing/Cloud | C20: =+Charges!B35 -> 111.44 | E20: 78. Reprises sur amortis., dépréciations et provisions | F20: 0 | G20: 0
A21: 627. Services bancaires et assimilés | E21: 79. Transferts de charges | F21: 0 | G21: 0
A22: 62780. Autres frais et commissions sur prest. de service (comptes) | B22: 15 | C22: =+Charges!B37 -> 195.11 | E22: TOTAL PRODUITS | F22: =+F5+F8+F9+F10+F11+F15+F17+F20+F21 -> 4896 | G22: =+G5+G8+G9+G10+G11+G15+G17+G20+G21 -> 10502.54
A23: 62780. Autres frais et commissions sur prest. de service (CB) | C23: =+Charges!B38 -> 0
A24: 6283. Concours divers (contribution tenue commune par ex.) | C24: =+Charges!B39 -> 0 | E24: Tabeau rempli automatiquement à partir des charges et produits saisis
A25: 628. Divers
A26: 6281. Concours divers (cotisations + droits GODF) | C26: =+Charges!B41 -> 4034
A27: 6281. Concours divers (cotisations CAALA) | B27: 190 | C27: =+Charges!B42 -> 316
A28: 63. Impôts, taxes et versements assimilés | B28: 0 | C28: 0
A29: 64. Charges de personnel | B29: 0 | C29: 0
A30: 65. Autres charges de gestion courante | B30: =SUM(B31) -> 400 | C30: =SUM(C31) -> 791.97
A31: 658. Charges diverses : versements au compte de solidarité | B31: 400 | C31: =+Charges!B47 -> 791.97
A32: 66. Charges financières | B32: 0 | C32: 0
A33: 67. Charges exceptionnelles | B33: =SUM(B34:B36) -> 600 | C33: =SUM(C34:C36) -> 791.97
A34: 671. Solidarité : don à la Fondation du GODF par ex. | C34: =+Charges!B48 -> 791.97
A35: 6721. Autres charges exceptionnelles (fleurs obsèques) | C35: =+Charges!B52 -> 0
A36: 6725. Autres charges exceptionnelles | B36: 600 | C36: =+Charges!B53 -> 0
A37: 68. Dotation. aux amortis., dépréciations et provisions | B37: 0 | C37: 0
A38: 69. Particip. Des salariés - Impôts sur les bénéf. et assimilés | B38: 0 | C38: 0
A39: TOTAL CHARGES HORS RESULTAT | B39: =B5+B10+B16+B28+B29+B30+B32+B33+B37+B38 -> 5296 | C39: =C5+C10+C16+C28+C29+C30+C32+C33+C37+C38 -> 12643.75
A40: RESULTAT | B40: =+F22-B39 -> -400 | C40: =+G22-C39 -> -2141.21
A41: TOTAL CHARGES | B41: =B39+B40 -> 4896 | C41: =C39+C40 -> 10502.54

Sheet Charges
A1: CHARGES | D1: FACTURES
A3: Tabeau rempli automatiquement à partir des comptes saisis | E3: Dépenses banquet d'ordre | I3: Petit matériel | M3: Fournitures bureau | Q3: Autres achats
A4: 60. Achats | B4: =SUM(B6:B8) -> 516.86 | D4: Date | E4: 602 - Autres appro. | F4: Montant | H4: Date | I4: 6063 - Fourn. | J4: Montant | L4: Date | M4: 6064 - Fourn. Adm. | N4: Montant | P4: Date | Q4: 6064 - Autres | R4: Montant
A5: 602. Achats stockés – Autres approvisionnements (Banquet d'Ordre) | B5: =F15 -> 3855 | D5: 44917 | E5: Cheque catherine Agapes | F5: 3805 | H5: 44922 | I5: Rbst Ariane T Pixarprinting | J5: 139.58
A6: 6063. Fournitures d’entretien et de petit équipement | B6: =J15 -> 516.86 | D6: 44918 | E6: Rbst Michele Pierson | F6: 25 | H6: 45070 | I6: Achat tapis de Loge Comp | J6: 107.28
A7: 6064. Fournitures admin. | B7: =N15 -> 0 | D7: 44918 | E7: Rbst JM Mithouard | F7: 25 | H7: 45212 | I7: Virement tapuis maitre Paemelaire | J7: 270
A8: 6068. Autres matières et fournitures. | B8: =R15 -> 0
E15: TOTAL | F15: =SUM(F5:F14) -> 3855 | I15: TOTAL | J15: =SUM(J5:J14) -> 516.86 | M15: TOTAL | N15: =SUM(N5:N14) -> 0 | Q15: TOTAL | R15: =SUM(R5:R14) -> 0
E17: Frais fixes de location | I17: Location Mousson | M17: Location autre local | Q17: Assurances
A18: 61. Services extérieurs | B18: =SUM(B19:B22) -> 1600 | D18: Date | E18: 6132 Loc. fixe - Objet | F18: Montant | H18: Date | I18: 6132 Loc. variable - Objet | J18: Montant | L18: Date | M18: 6132 Loc. autre - Objet | N18: Montant | P18: Date | Q18: 616. Primes d'assurances | R18: Montant
A19: 613. Locations | H19: 45042 | I19: Paiement Salle Mousson | J19: 800 | L19: 44964 | M19: DEVILLY Allumage | N19: 100
A20: 6132. Locations immobilières fixe | B20: =F28 -> 0 | H20: 45173 | I20: Cheque | J20: 700
A21: 6132. Locations immobilières variables (Mousson) | B21: =J28 -> 1500
A22: 6132. Locations immobilières variables (autre) | B22: =N28 -> 100
A23: 616. Primes d'assurances | B23: =R28 -> 0
E28: TOTAL | F28: =SUM(F19:F27) -> 0 | I28: TOTAL | J28: =SUM(J19:J27) -> 1500 | M28: TOTAL | N28: =SUM(N19:N27) -> 100 | Q28: TOTAL | R28: =SUM(R19:R27) -> 0
E30: Notes de frais | I30: Timbres, recommandés | M30: Abonnement cloud… | Q30: Frais gestion compte bancaire | U30: Frais carte bancaire | AC30: Factures GODF | AG30: Factures CAALA
A31: 62. Autres services extérieurs | B31: =SUM(B32:B42) -> 5087.95 | D31: Date | E31: 625 Dépl. - Objet | F31: Montant | H31: Date | I31: 6261 Affranch. - Objet | J31: Montant | L31: Date | M31: 6262 Mail./Cloud. - Objet | N31: Montant | P31: Date | Q31: 62780 Frais gest. banq. - Objet | R31: Montant | T31: Date | U31: 62780 Frais gest. CB - Objet | V31: Montant | X31: Date | Y31: 62780 Concours divers - Objet | Z31: Montant | AB31: Date | AC31: 62780 Cotis. + droits GODF - Objet | AD31: Montant | AF31: Date | AG31: 62780 Cotis. + droits CAALA - Objet | AH31: Montant
A32: 625. Déplacements, missions et réceptions | B32: =F42 -> 431.4 | D32: 45161 | E32: Frais convent | F32: 431.4 | L32: 45082 | M32: LWS Internet | N32: 111.44 | P32: 44893 | Q32: Cotisation Adispo Asso Classique | R32: 11.15 | AB32: 44956 | AC32: Paiement 1er Trim GODF | AD32: 1144 | AF32: 45033 | AG32: Cheque solidarité + Frais | AH32: 270
A33: 626. Frais postaux et de télécommunications | P33: 44943 | Q33: Cotisation Adispo Asso Classique | R33: 19.74 | AB33: 44977 | AC33: Rbst avance GODF FR AUER | AD33: 600 | AF33: 45097 | AG33: Cheque | AH33: 46
A34: 6261. Affranchissements | B34: =J42 -> 0 | P34: 45034 | Q34: Cotisation Adispo Asso Classique | R34: 19.74 | AB34: 45042 | AC34: Paiement 2ème Trimestre | AD34: 1144
A35: 6262. Abonnement Mailing/Cloud | B35: =N42 -> 111.44 | P35: 45125 | Q35: Cotisation Adispo Asso Classique | R35: 19.74 | AB35: 45093 | AC35: Paiement 3ème trimestre capitation | AD35: 1146
A36: 627. Services bancaires et assimilés | P36: 45216 | Q36: Cotisation Adispo Asso Classique | R36: 19.74
A37: 62780. Autres frais et commissions sur prest. de service (comptes) | B37: =R42 -> 195.11 | Q37: Adhesion Credit mutuel | R37: 15
A38: 62780. Autres frais et commissions sur prest. de service (CB) | B38: =V42 -> 0 | Q38: Resiliation Banque Postale | R38: 90
A39: 6283. Concours divers (contribution tenue commune par ex.) | B39: =Z42 -> 0
A40: 628. Divers
A41: 6281. Concours divers (cotisations + droits GODF) | B41: =AD42 -> 4034
A42: 6281. Concours divers (cotisations CAALA) | B42: =AH42 -> 316 | E42: TOTAL | F42: =SUM(F32:F41) -> 431.4 | I42: TOTAL | J42: =SUM(J32:J41) -> 0 | M42: TOTAL | N42: =SUM(N32:N41) -> 111.44 | Q42: TOTAL | R42: =SUM(R32:R41) -> 195.11 | U42: TOTAL | V42: =SUM(V32:V41) -> 0 | Y42: TOTAL | Z42: =SUM(Z32:Z41) -> 0 | AC42: TOTAL | AD42: =SUM(AD32:AD41) -> 4034 | AG42: TOTAL | AH42: =SUM(AH32:AH41) -> 316
E44: Charges diverses | I44: Dons, médailles | M44: Fleurs / obsèques…
A45: 63. Impôts, taxes et versements assimilés | B45: 0 | D45: Date | E45: 658 Charg. div. - Objet | F45: Montant | H45: Date | I45: 671 Solidarité. - Objet | J45: Montant | L45: Date | M45: 6721 Autres ch. excep. - Objet | N45: Montant
A46: 64. Charges de personnel | B46: 0 | E46: TDV 1 | F46: 468.48
A47: 65. Autres charges de gestion courante | B47: =SUM(B48) -> 791.97 | E47: TDV 2 | F47: 323.49
A48: 658. Charges diverses : versements au cte de solidarité par ex. | B48: =F56 -> 791.97
A49: 66. Charges financières | B49: 0
A51: 67. Charges exceptionnelles | B51: =SUM(B52:B53) -> 0
A52: 671. Solidarité : don à la Fondation du GODF | B52: =J56 -> 0
A53: 6721. Autres charges exceptionnelles (fleurs ...) | B53: =N56 -> 0
A54: 68. Dotation. aux amortis., dépréciations et provisions | B54: 0
A55: 69. Particip. Des salariés - Impôts sur les bénéf. et assimilés | B55: 0
...

Sheet Produits
A1: PRODUITS | D1: SOMMES PERÇUES
A3: Tabeau rempli automatiquement à partir des comptes saisis | E3: Médailles reçues | H3: NOM | I3: Prénom | J3: GODF | K3: CAALA | L3: SOCRATE | M3: TOTAL DÛ | N3: PAYÉ | O3: SOLDE
A4: 70. Ventes de prod. fabriqués, prest. services, marchandises | B4: =SUM(B5:B6) -> 3277.24 | D4: Date | E4: 74. Subventions d'exploitation | F4: Montant | H4: AGNOUNA ONANA | I4: Alphonse | J4: 171.7 | K4: 4 | L4: =P4-K4-J4 -> 153 | M4: =J4+K4+L4 -> 328.7 | N4: 0 | O4: =M4-N4 -> 328.7 | P4: 328.7 | Q4: 237.7
A5: 701. Billeterie BO membres | D5: 44900 | E5: Harmonie Esperance | F5: 50 | H5: AUER | I5: François Régis | J5: 171.7 | K5: 4 | L5: =P5-K5-J5 -> 153 | M5: =J5+K5+L5 -> 328.7 | N5: 328.7 | O5: =M5-N5 -> 0 | P5: 328.7 | Q5: 282.7
A6: 701. Billeterie BO visiteurs | B6: 3277.24 | D6: 44903 | E6: Amis de Regle et l'infini | F6: 100 | H6: BUR | I6: Patrick | J6: 171.7 | K6: 4 | L6: =P6-K6-J6 -> 153 | M6: =J6+K6+L6 -> 328.7 | N6: 328.7 | O6: =M6-N6 -> 0 | P6: 328.7 | Q6: 328.7
A7: 71. Production stockée | B7: 0 | D7: 44904 | E7: Noble Amitié | F7: 300 | H7: BUTTERLIN | I7: Christophe | J7: 171.7 | K7: 4 | L7: =P7-K7-J7 -> 199 | M7: =J7+K7+L7 -> 374.7 | N7: 374.7 | O7: =M7-N7 -> 0 | P7: =298.7+76 -> 374.7 | Q7: 374.7
A8: 72. Production immobilisée | B8: 0 | D8: 44914 | E8: Medaille Saint Antoine et des Amis Réunis | F8: 300 | H8: CADONA | I8: Alain | J8: 171.7 | K8: 4 | L8: =P8-K8-J8 -> 199 | M8: =J8+K8+L8 -> 374.7 | N8: 374.7 | O8: =M8-N8 -> 0 | P8: =298.7+76 -> 374.7 | Q8: 420.7
A9: 74. Subventions d'exploitation | B9: =+F21 -> 3245 | D9: 44935 | E9: Double Union medaille | F9: 200 | H9: CHANSON | I9: Claire | J9: 171.7 | K9: 4 | L9: =P9-K9-J9 -> 199 | M9: =J9+K9+L9 -> 374.7 | N9: 374.7 | O9: =M9-N9 -> 0 | P9: =298.7+76 -> 374.7
A10: 75. Autres produits de gestion courante | B10: =SUM(B11:B13) -> 7225.3 | D10: 44944 | E10: Remise de cheques | F10: 45 | H10: CLERC | I10: Florence | J10: 171.7 | K10: 4 | L10: =P10-K10-J10 -> -175.7 | M10: =J10+K10+L10 -> 0 | O10: =M10-N10 -> 0
A11: 756. Cotisations | D11: 44944 | E11: Remise de cheques | F11: 100 | H11: CORNELISE | I11: Claire | J11: 171.7 | K11: 4 | L11: =P11-K11-J11 -> 245 | M11: =J11+K11+L11 -> 420.7 | N11: 420.7 | O11: =M11-N11 -> 0 | P11: 420.7
A12: 7561. Cotisations membres | B12: =+N32 -> 7225.3 | D12: 44944 | E12: Remise de cheques | F12: 350 | H12: DANGOUMAU | I12: Tristan | J12: 171.7 | K12: 4 | L12: =P12-K12-J12 -> 153 | M12: =J12+K12+L12 -> 328.7 | N12: 328.7 | O12: =M12-N12 -> 0 | P12: 328.7
A13: 758. Produits divers de gestion courante | B13: =+F51 -> 0 | D13: 44945 | E13: Asso Philosophique Loge Paris | F13: 100 | H13: DARDENNE | I13: Gilles | J13: 171.7 | K13: 4 | L13: =P13-K13-J13 -> 199 | M13: =J13+K13+L13 -> 374.7 | N13: 374.7 | O13: =M13-N13 -> 0 | P13: 374.7
A14: 76. Produits financiers | B14: =SUM(B15) -> 0 | D14: 44963 | E14: Amour et Liberté Medaille | F14: 300 | H14: DEL VECCHIO | I14: Jean Pierre | J14: 171.7 | K14: 4 | L14: =P14-K14-J14 -> 199 | M14: =J14+K14+L14 -> 374.7 | N14: 374.7 | O14: =M14-N14 -> 0 | P14: 374.7
A15: 768. Autres produits financiers. | B15: =+F37 -> 0 | D15: 44965 | E15: Remsie cheques | F15: 200 | H15: DILLENSCHNEIDER | I15: Michel | J15: 171.7 | K15: 4 | L15: =P15-K15-J15 -> 153 | M15: =J15+K15+L15 -> 328.7 | N15: 328.7 | O15: =M15-N15 -> 0 | P15: 328.7
A16: 77. Produits exceptionnels | B16: =SUM(B17:B17) -> 0 | D16: 44971 | E16: Cairn et Acacia | F16: 100 | H16: DUBOIS | I16: Jean-Luc | J16: 171.7 | K16: 4 | L16: =P16-K16-J16 -> 153 | M16: =J16+K16+L16 -> 328.7 | N16: 328.7 | O16: =M16-N16 -> 0 | P16: 328.7
A17: 77181. Autres prod. except. sur op. de gestion | B17: =F65 -> 0 | D17: 44977 | E17: Vitruve | F17: 100 | H17: DUPONT | I17: Nicolas | L17: =P17-K17-J17 -> 153 | M17: =J17+K17+L17 -> 153 | N17: 153 | O17: =M17-N17 -> 0 | P17: 153
A18: 77185. Remboursement trop perçu | B18: =F80 -> 30 | D18: 45013 | E18: Medailel CAALA | F18: 800 | H18: FAIVRE | I18: Alain | J18: 171.7 | K18: 4 | L18: =P18-K18-J18 -> 199 | M18: =J18+K18+L18 -> 374.7 | N18: 374.7 | O18: =M18-N18 -> 0 | P18: 374.7
A19: 78. Reprises sur amortis., dépréciations et provisions | B19: 0 | D19: 45070 | E19: Remise de cheques | F19: 200 | H19: GUERNE | I19: Dominique | L19: =P19-K19-J19 -> 107 | M19: =J19+K19+L19 -> 107 | N19: 107 | O19: =M19-N19 -> 0 | P19: =31+76 -> 107
A20: 79. Transferts de charges | B20: 0 | H20: IBBA | I20: Jean-Marc | J20: 171.7 | K20: 4 | L20: =P20-K20-J20 -> 153 | M20: =J20+K20+L20 -> 328.7 | N20: 328.7 | O20: =M20-N20 -> 0 | P20: =252.7+76 -> 328.7
E21: TOTAL | F21: =SUM(F5:F20) -> 3245 | H21: KLEIN | I21: Thomas | L21: =P21-K21-J21 -> 153 | M21: =J21+K21+L21 -> 153 | N21: 153 | O21: =M21-N21 -> 0 | P21: =77+76 -> 153
A22: Pas de tableau concernant les billeteries : à concevoir le cas échéant | H22: LEBOSSÉ | I22: Cédric | J22: 171.7 | K22: 4 | L22: =P22-K22-J22 -> 153 | M22: =J22+K22+L22 -> 328.7 | N22: 328.7 | O22: =M22-N22 -> 0 | P22: =252.7+76 -> 328.7
H23: LUZERNE | I23: Christian | J23: 171.7 | K23: 4 | L23: =P23-K23-J23 -> 153 | M23: =J23+K23+L23 -> 328.7 | N23: 328.7 | O23: =M23-N23 -> 0 | P23: 328.7
H24: POIAREZ | I24: Jean Claude | J24: 171.7 | K24: 4 | L24: =P24-K24-J24 -> 107 | M24: =J24+K24+L24 -> 282.7 | N24: 282.7 | O24: =M24-N24 -> 0 | P24: =206.7+76 -> 282.7
E25: Intérêts compte épargne | H25: REYTER | I25: Grégory | L25: =P25-K25-J25 -> 199 | M25: =J25+K25+L25 -> 199 | N25: 199 | O25: =M25-N25 -> 0 | P25: =123+76 -> 199
D26: Date | E26: 768. Autres produits financiers. | F26: Montant | H26: ROCHE | I26: Dominique | J26: 171.7 | K26: 4 | L26: =P26-K26-J26 -> 199 | M26: =J26+K26+L26 -> 374.7 | N26: 374.7 | O26: =M26-N26 -> 0 | P26: =298.7+76 -> 374.7
H27: SUSSET | I27: Valérie | J27: 171.7 | K27: 4 | L27: =P27-K27-J27 -> 153 | M27: =J27+K27+L27 -> 328.7 | N27: 328.7 | O27: =M27-N27 -> 0 | P27: =252.7+76 -> 328.7
H28: TRUFFERT | I28: Ariane | J28: 171.7 | K28: 4 | L28: =P28-K28-J28 -> 153 | M28: =J28+K28+L28 -> 328.7 | N28: 328.7 | O28: =M28-N28 -> 0 | P28: 328.7
N32: =SUM(N4:N31) -> 7225.3 | O32: =SUM(O4:O31) -> 328.7
H35: Pour les affiliés, pas de cotisations GODF et CAALA
E37: TOTAL | F37: =SUM(F27:F36) -> 0
E39: Paiements de droits et décors impétrants par ex.
D40: Date | E40: 758. Produits divers de gestion courante | F40: Montant
E51: TOTAL | F51: =SUM(F41:F50) -> 0
D54: Date | E54: 77181. Autres prod. except. sur op. de gestion | F54: Montant
E65: TOTAL | F65: =SUM(F55:F64) -> 0
E68: Remboursements (GODF…)
D69: Date | E69: 77185. Remboursement / trop perçu | F69: Montant
E70: Caala solidarité | F70: 30
E80: TOTAL | F80: =SUM(F70:F79) -> 30
