Workbook

Sheet Ne Pas transmettre  Tranches 
A1: Nom | B1: Prenom | C1: Tranche | D1: Affillié | E1: Montant demandé | F1: Tranche | G1: nb | H1: Colonne1 | I1: Affiliation | J1: Colonne2 | K1: Appartenance
A2: AGNOUNA ONANA | B2: Alphonse | C2: 1 | D2: A | E2: =IF(D2="A",INDEX(I$2:I$6,MATCH(C2,F$2:F$6,0)),INDEX(K$2:K$6,MATCH(C2,F$2:F$6,0))) -> 71 | F2: 1 | G2: 1 | H2: -0.6 | I2: ='Outil de Calcul'!D3 -> 71 | J2: 68 | K2: ='Outil de Calcul'!F3 -> 255.5
A3: AUER | B3: François Régis | C3: 2 | E3: =IF(D3="A",INDEX(I$2:I$6,MATCH(C3,F$2:F$6,0)),INDEX(K$2:K$6,MATCH(C3,F$2:F$6,0))) -> 307.5 | F3: 2 | G3: 4 | H3: -0.3 | I3: ='Outil de Calcul'!D4 -> 123 | J3: 476 | K3: ='Outil de Calcul'!F4 -> 307.5
A4: BUR | B4: Patrick | F4: 3 | G4: 15 | H4: 0 | I4: ='Outil de Calcul'!D5 -> 176 | J4: 2550 | K4: ='Outil de Calcul'!F5 -> 360.5
A5: Butterlin | B5: Christophe | C5: 3 | E5: =IF(D5="A",INDEX(I$2:I$6,MATCH(C5,F$2:F$6,0)),INDEX(K$2:K$6,MATCH(C5,F$2:F$6,0))) -> 360.5 | F5: 4 | G5: 4 | H5: 0.3 | I5: ='Outil de Calcul'!D6 -> 228 | J5: 884 | K5: ='Outil de Calcul'!F6 -> 412.5
A6: Cadona | B6: Alain | C6: 5 | E6: =IF(D6="A",INDEX(I$2:I$6,MATCH(C6,F$2:F$6,0)),INDEX(K$2:K$6,MATCH(C6,F$2:F$6,0))) -> 465.5 | F6: 5 | G6: 1 | H6: 0.6 | I6: ='Outil de Calcul'!D7 -> 281 | J6: 272 | K6: ='Outil de Calcul'!F7 -> 465.5
A7: CHANSON | B7: Claire
A8: CORNELISE | B8: Claire | C8: 4 | E8: =IF(D8="A",INDEX(I$2:I$6,MATCH(C8,F$2:F$6,0)),INDEX(K$2:K$6,MATCH(C8,F$2:F$6,0))) -> 412.5
A9: Dangoumau | B9: Tristan | C9: 3 | E9: =IF(D9="A",INDEX(I$2:I$6,MATCH(C9,F$2:F$6,0)),INDEX(K$2:K$6,MATCH(C9,F$2:F$6,0))) -> 360.5
A10: Dardenne | B10: Gilles | C10: 4 | E10: =IF(D10="A",INDEX(I$2:I$6,MATCH(C10,F$2:F$6,0)),INDEX(K$2:K$6,MATCH(C10,F$2:F$6,0))) -> 412.5
A11: DEL VECCHIO | B11: Jean Pierre | C11: 3 | E11: =IF(D11="A",INDEX(I$2:I$6,MATCH(C11,F$2:F$6,0)),INDEX(K$2:K$6,MATCH(C11,F$2:F$6,0))) -> 360.5
A12: DILLENSCHNEIDER | B12: Michel | C12: 1 | E12: =IF(D12="A",INDEX(I$2:I$6,MATCH(C12,F$2:F$6,0)),INDEX(K$2:K$6,MATCH(C12,F$2:F$6,0))) -> 255.5
A13: DUBOIS | B13: Jean-Luc | C13: 3 | E13: =IF(D13="A",INDEX(I$2:I$6,MATCH(C13,F$2:F$6,0)),INDEX(K$2:K$6,MATCH(C13,F$2:F$6,0))) -> 360.5
A14: Dupont | B14: Nicolas | C14: 3 | D14: A | E14: =IF(D14="A",INDEX(I$2:I$6,MATCH(C14,F$2:F$6,0)),INDEX(K$2:K$6,MATCH(C14,F$2:F$6,0))) -> 176
A15: FAIVRE | B15: Alain | C15: 4 | E15: =IF(D15="A",INDEX(I$2:I$6,MATCH(C15,F$2:F$6,0)),INDEX(K$2:K$6,MATCH(C15,F$2:F$6,0))) -> 412.5
A16: Guerné | B16: Dominique | C16: 2 | E16: =IF(D16="A",INDEX(I$2:I$6,MATCH(C16,F$2:F$6,0)),INDEX(K$2:K$6,MATCH(C16,F$2:F$6,0))) -> 307.5
A17: Ibba | B17: Jean marc | C17: 3 | E17: =IF(D17="A",INDEX(I$2:I$6,MATCH(C17,F$2:F$6,0)),INDEX(K$2:K$6,MATCH(C17,F$2:F$6,0))) -> 360.5
A18: Kaizer | B18: Nicolas | C18: 1 | D18: A | E18: =IF(D18="A",INDEX(I$2:I$6,MATCH(C18,F$2:F$6,0)),INDEX(K$2:K$6,MATCH(C18,F$2:F$6,0))) -> 71
A19: Klein | B19: Thomas | C19: 4 | D19: A | E19: =IF(D19="A",INDEX(I$2:I$6,MATCH(C19,F$2:F$6,0)),INDEX(K$2:K$6,MATCH(C19,F$2:F$6,0))) -> 228
A20: LEBOSSÉ | B20: Cédric | C20: 3 | E20: =IF(D20="A",INDEX(I$2:I$6,MATCH(C20,F$2:F$6,0)),INDEX(K$2:K$6,MATCH(C20,F$2:F$6,0))) -> 360.5
A21: LEROY | B21: Christine | C21: 3 | E21: =IF(D21="A",INDEX(I$2:I$6,MATCH(C21,F$2:F$6,0)),INDEX(K$2:K$6,MATCH(C21,F$2:F$6,0))) -> 360.5
A22: luzerne | B22: Christian
A23: MAITREPIERRE | B23: Anne-Sophie | C23: 3 | E23: =IF(D23="A",INDEX(I$2:I$6,MATCH(C23,F$2:F$6,0)),INDEX(K$2:K$6,MATCH(C23,F$2:F$6,0))) -> 360.5
A24: MANGENOT | B24: Gerard | C24: 4 | E24: =IF(D24="A",INDEX(I$2:I$6,MATCH(C24,F$2:F$6,0)),INDEX(K$2:K$6,MATCH(C24,F$2:F$6,0))) -> 412.5
A25: POIAREZ | B25: Jean Claude | C25: 3 | E25: =IF(D25="A",INDEX(I$2:I$6,MATCH(C25,F$2:F$6,0)),INDEX(K$2:K$6,MATCH(C25,F$2:F$6,0))) -> 360.5
A26: POLLO | B26: Michel | C26: 3 | E26: =IF(D26="A",INDEX(I$2:I$6,MATCH(C26,F$2:F$6,0)),INDEX(K$2:K$6,MATCH(C26,F$2:F$6,0))) -> 360.5
A27: REYTER | B27: grégory | C27: 3 | D27: A | E27: =IF(D27="A",INDEX(I$2:I$6,MATCH(C27,F$2:F$6,0)),INDEX(K$2:K$6,MATCH(C27,F$2:F$6,0))) -> 176
A28: ROCHE | B28: Dominique | I28: ici on saisit la tranche et si on est affilié ou pas avec un A
A29: SEYLER | B29: Muriel | C29: 3 | E29: =IF(D29="A",INDEX(I$2:I$6,MATCH(C29,F$2:F$6,0)),INDEX(K$2:K$6,MATCH(C29,F$2:F$6,0))) -> 360.5 | I29: colonne C et D uniquement
A30: SEYLER | B30: Synthia | C30: 3 | E30: =IF(D30="A",INDEX(I$2:I$6,MATCH(C30,F$2:F$6,0)),INDEX(K$2:K$6,MATCH(C30,F$2:F$6,0))) -> 360.5
A31: SUSSET | B31: Valérie | C31: 3 | E31: =IF(D31="A",INDEX(I$2:I$6,MATCH(C31,F$2:F$6,0)),INDEX(K$2:K$6,MATCH(C31,F$2:F$6,0))) -> 360.5
A32: TRIEUX | B32: jean-Baptiste | C32: 2 | E32: =IF(D32="A",INDEX(I$2:I$6,MATCH(C32,F$2:F$6,0)),INDEX(K$2:K$6,MATCH(C32,F$2:F$6,0))) -> 307.5
A33: TRUFFERT | B33: Ariane | C33: 2 | E33: =IF(D33="A",INDEX(I$2:I$6,MATCH(C33,F$2:F$6,0)),INDEX(K$2:K$6,MATCH(C33,F$2:F$6,0))) -> 307.5
A49: Colonne1 | B49: Colonne2 | C49: Colonne3
A50: Tranche 1 | B50: 1 | C50: =COUNTIF(C$2:C$46,B50) -> 3
A51: Tranche 2 | B51: 2 | C51: =COUNTIF(C$2:C$46,B51) -> 4
A52: Tranche 3 | B52: 3 | C52: =COUNTIF(C$2:C$46,B52) -> 15
A53: Tranche 4 | B53: 4 | C53: =COUNTIF(C$2:C$46,B53) -> 5
A54: Tranche 5 | B54: 5 | C54: =COUNTIF(C$2:C$46,B54) -> 1
B55: Total | C55: =SUM(C50:C54) -> 28
...

Sheet Budget  Previsionnel
A2: Année civile | B2: 2023 | C2: 2024 | D2: 2025 | E2: 2026 | F2: 2027 | G2: 2028 | H2: 2029 | I2: 2030
B3: ='Ne Pas transmettre Tranches '!C50 -> 3
A4: Membres * | B4: 20 | C4: 19 | D4: ='Ne Pas transmettre Tranches '!C55-'Ne Pas transmettre Tranches '!D57 -> 23 | E4: 23 | F4: 26 | G4: 28 | H4: 30 | I4: 32
A5: Affiliés | B5: 4 | C5: 9 | D5: ='Ne Pas transmettre Tranches '!D57 -> 5 | E5: 7 | F5: 7 | G5: 6 | H5: 6 | I5: 6
A6: Effectif total | B6: =SUM(B4:B5) -> 24 | C6: =SUM(C4:C5) -> 28 | D6: =SUM(D4:D5) -> 28 | E6: =SUM(E4:E5) -> 30 | F6: =SUM(F4:F5) -> 33 | G6: =SUM(G4:G5) -> 34 | H6: =SUM(H4:H5) -> 36 | I6: =SUM(I4:I5) -> 38
A8: TENUES | B8: 20 | C8: 20 | D8: 20 | E8: 20 | F8: 20 | G8: 20 | H8: 20 | I8: 20
A10: Achats | B10: 1066 | C10: 500 | D10: 500 | E10: 500 | F10: 500 | G10: 500 | H10: 500 | I10: 500
A11: Locations Mousson (100 X nb ten.) | B11: =B8*100 -> 2000 | C11: =C8*100 -> 2000 | D11: 2400 | E11: 2400 | F11: 2400 | G11: 2400 | H11: 2400 | I11: 2400
A12: Assurances | B12: =140/4 -> 35 | C12: 0 | D12: 0 | E12: 0 | F12: 0 | G12: 0 | H12: 0 | I12: 0 | K12: ici c'est le budget prévisionnel
A13: Frais Convent | B13: 500 | C13: 500 | D13: 500 | E13: 500 | F13: 500 | G13: 500 | H13: 500 | I13: 500 | K13: on saisit juste en cellule D4 et D5 les nombres d'appartenances et d'affiliés
A14: Solidarité/frais CAALA | B14: 190 | C14: 190 | D14: 190 | E14: 190 | F14: 190 | G14: 190 | H14: 190 | I14: 190 | K14: en ensuite de la lignes 10 à 20
A15: Affranchissements | B15: 10 | C15: 0 | D15: 10 | E15: 35 | F15: 35 | G15: 35 | H15: 35 | I15: 35 | K15: eventuellement lignes 25 et 26
A16: Abonnement numérique | B16: 0 | C16: 111 | D16: 111 | E16: 111 | F16: 111 | G16: 111 | H16: 111 | I16: 111 | K16: on met à jour la capitation dans les lignes 33 et 34
A17: Frais gestion banque | B17: =5*3 -> 15 | C17: 0 | D17: =5*12 -> 60 | E17: =5*12 -> 60 | F17: =5*12 -> 60 | G17: =5*12 -> 60 | H17: =5*12 -> 60 | I17: =5*12 -> 60
A18: Taxes et augementation grade et decors | B18: 0 | C18: 0 | D18: 120 | E18: 240 | F18: 240 | G18: 240 | H18: 240 | I18: 240
A19: Dépenses exceptionnelles | B19: 600 | C19: 400 | D19: 300 | E19: 300 | F19: 300 | G19: 300 | H19: 300 | I19: 300
A20: Banquet d'ordre | B20: =B6*20 -> 480 | C20: =28*20 -> 560 | D20: =D6*20 -> 560 | E20: =E6*20 -> 600 | F20: =F6*20 -> 660 | G20: =G6*20 -> 680 | H20: =H6*20 -> 720 | I20: =I6*20 -> 760
A21: TOTAL DEPENSES Socrate | B21: =SUM(B10:B20) -> 4896 | C21: =SUM(C10:C20) -> 4261 | D21: =SUM(D10:D20) -> 4751 | E21: =SUM(E10:E20) -> 4936 | F21: =SUM(F10:F20) -> 4996 | G21: =SUM(G10:G20) -> 5016 | H21: =SUM(H10:H20) -> 5056 | I21: =SUM(I10:I20) -> 5096
A22: Capitations GO + CAALA | B22: =B4*(B33+B34) -> 3514 | C22: =C4*(C33+C34) -> 3338.3 | D22: =D4*(D33+D34) -> 4243.5 | E22: =E4*(E33+E34) -> 4243.5 | F22: =F4*(F33+F34) -> 4797 | G22: =G4*(G33+G34) -> 5166 | H22: =H4*(H33+H34) -> 5535 | I22: =I4*(I33+I34) -> 5904
A23: TOTAL DEPENSES BUDGET | B23: =B21+B22 -> 8410 | C23: =C21+C22 -> 7599.3 | D23: =D21+D22 -> 8994.5 | E23: =E21+E22 -> 9179.5 | F23: =F21+F22 -> 9793 | G23: =G21+G22 -> 10182 | H23: =H21+H22 -> 10591 | I23: =I21+I22 -> 11000
A25: Médaille Région | B25: 800
A26: Médailles Loges | B26: =100+100+200+300+300+50+50+200 -> 1300
A27: Cotisations Socrate | B27: =B28-B26-B25 -> 2796 | C27: =C28-C26-C25 -> 4261 | D27: =D28-D26-D25 -> 4751 | E27: =E28-E26-E25 -> 4936 | F27: =F28-F26-F25 -> 4996 | G27: =G28-G26-G25 -> 5016 | H27: =H28-H26-H25 -> 5056 | I27: =I28-I26-I25 -> 5096
A28: TOTAL RECETTES Socrate | B28: =B21 -> 4896 | C28: =C21 -> 4261 | D28: =D21 -> 4751 | E28: =E21 -> 4936 | F28: =F21 -> 4996 | G28: =G21 -> 5016 | H28: =H21 -> 5056 | I28: =I21 -> 5096
A29: Capitations GO + CAALA | B29: =B4*(B33+B34) -> 3514 | C29: =C4*(C33+C34) -> 3338.3 | D29: =D4*(D33+D34) -> 4243.5 | E29: =E4*(E33+E34) -> 4243.5 | F29: =F4*(F33+F34) -> 4797 | G29: =G4*(G33+G34) -> 5166 | H29: =H4*(H33+H34) -> 5535 | I29: =I4*(I33+I34) -> 5904
A30: TOTAL RECETTES BUDGET | B30: =B28+B4*(B33+B34) -> 8410 | C30: =C28+C4*(C33+C34) -> 7599.3 | D30: =D28+D4*(D33+D34) -> 8994.5 | E30: =E28+E4*(E33+E34) -> 9179.5 | F30: =F28+F4*(F33+F34) -> 9793 | G30: =G28+G4*(G33+G34) -> 10182 | H30: =H28+H4*(H33+H34) -> 10591 | I30: =I28+I4*(I33+I34) -> 11000
A32: Cotisation Socrate ** *** | B32: =B27/B6 -> 116.5 | C32: =C27/C6 -> 152.17857 | D32: =D27/D6 -> 169.67857 | E32: =E27/E6 -> 164.53333 | F32: =F27/F6 -> 151.39394 | G32: =G27/G6 -> 147.52941 | H32: =H27/H6 -> 140.44444 | I32: =I27/I6 -> 134.10526 | J32: <----- | K32: cotisation afiiliés non diférenciée, ne pas transmettre , c'est juste pour avoir une idée
A33: Capitation GODF | B33: 171.7 | C33: 171.7 | D33: 180.5 | E33: 180.5 | F33: 180.5 | G33: 180.5 | H33: 180.5 | I33: 180.5
A34: Capitation CAALA | B34: 4 | C34: 4 | D34: 4 | E34: 4 | F34: 4 | G34: 4 | H34: 4 | I34: 4
A35: COTISATION MEMBRE | B35: =SUM(B32:B34) -> 292.2 | C35: =SUM(C32:C34) -> 327.87857 | D35: =SUM(D32:D34) -> 354.17857 | E35: =SUM(E32:E34) -> 349.03333 | F35: =SUM(F32:F34) -> 335.89394 | G35: =SUM(G32:G34) -> 332.02941 | H35: =SUM(H32:H34) -> 324.94444 | I35: =SUM(I32:I34) -> 318.60526 | J35: <---- | K35: cotisation non diférenciée, ne pas transmettre , c'est juste pour avoir une idée
A36: * Capitations des premiers initiés de la Loge comptées en année pleine
A37: ** dont participation 20€ à 1 banquet d'ordre à partir de 2023 (membres et affiliés)
A38: *** montant de la cotisation des affiliés
A40: Pour info, cotisations hors BO : | B40: =B32 -> 116.5 | C40: =C32-20 -> 132.17857 | D40: =D32-20 -> 149.67857 | E40: =E32-20 -> 144.53333 | F40: =F32-20 -> 131.39394 | G40: =G32-20 -> 127.52941 | H40: =H32-20 -> 120.44444 | I40: =I32-20 -> 114.10526
B41: =B35 -> 292.2 | C41: =C35-20 -> 307.87857 | D41: =D35-20 -> 334.17857 | E41: =E35-20 -> 329.03333 | F41: =F35-20 -> 315.89394 | G41: =G35-20 -> 312.02941 | H41: =H35-20 -> 304.94444 | I41: =I35-20 -> 298.60526
A42: NOTA : pour chaque initiation compter l'achat des gants et tabliers + droits d'enregistrement GO à facturer aux néophytes.

Sheet Outil de Calcul
A2: Tranche | B2: Nb de FF et SS | C2: % | D2: Montant tranche Affiliés | E2: Montant Total | F2: Cotisation Globale | G2: Total
A3: Tranche 1 | B3: ='Ne Pas transmettre Tranches '!C50 -> 3 | C3: -0.6 | D3: =ROUNDUP(G$15*(1+C3),0) -> 71 | E3: =B3*D3 -> 213 | F3: =Tableau12[[#This Row],[Montant tranche Affiliés]]+B$15 -> 255.5 | G3: =Tableau12[[#This Row],[Nb de FF et SS]]*Tableau12[[#This Row],[Cotisation Globale]] -> 766.5
A4: Tranche 2 | B4: ='Ne Pas transmettre Tranches '!C51 -> 4 | C4: -0.3 | D4: =ROUNDUP(G$15*(1+C4),0) -> 123 | E4: =B4*D4 -> 492 | F4: =Tableau12[[#This Row],[Montant tranche Affiliés]]+B$15 -> 307.5 | G4: =Tableau12[[#This Row],[Nb de FF et SS]]*Tableau12[[#This Row],[Cotisation Globale]] -> 1230
A5: Tranche 3 | B5: ='Ne Pas transmettre Tranches '!C52 -> 15 | C5: 0 | D5: =ROUNDUP(G$15*(1+C5),0) -> 176 | E5: =B5*D5 -> 2640 | F5: =Tableau12[[#This Row],[Montant tranche Affiliés]]+B$15 -> 360.5 | G5: =Tableau12[[#This Row],[Nb de FF et SS]]*Tableau12[[#This Row],[Cotisation Globale]] -> 5407.5
A6: Tranche 4 | B6: ='Ne Pas transmettre Tranches '!C53 -> 5 | C6: 0.3 | D6: =ROUNDUP(G$15*(1+C6),0) -> 228 | E6: =B6*D6 -> 1140 | F6: =Tableau12[[#This Row],[Montant tranche Affiliés]]+B$15 -> 412.5 | G6: =Tableau12[[#This Row],[Nb de FF et SS]]*Tableau12[[#This Row],[Cotisation Globale]] -> 2062.5
A7: Tranche 5 | B7: ='Ne Pas transmettre Tranches '!C54 -> 1 | C7: 0.6 | D7: =ROUNDUP(G$15*(1+C7),0) -> 281 | E7: =B7*D7 -> 281 | F7: =Tableau12[[#This Row],[Montant tranche Affiliés]]+B$15 -> 465.5 | G7: =Tableau12[[#This Row],[Nb de FF et SS]]*Tableau12[[#This Row],[Cotisation Globale]] -> 465.5
A8: Total | B8: =SUM(B3:B7) -> 28 | E8: =SUM(E3:E7) -> 4766 | G8: =SUM(G3:G7) -> 9932
A10: Nb Affiliés | B10: ='Ne Pas transmettre Tranches '!D57 -> 5 | D10: montant à demander aux affiliations | F10: montant à demander aux appartenances
C14: Budget Total | D14: ='Budget Previsionnel'!D23 -> 8994.5 | F14: Montant median Quote Part Socrate
A15: Capitation + Region | B15: ='Budget Previsionnel'!D33+'Budget Previsionnel'!D34 -> 184.5 | C15: budget hors capitation | D15: =D14-B15*(B8-B10) -> 4751 | F15: X | G15: =D15/(B3*(1+C3)+B4*(1+C4)+B5*(1+C5)+B6*(1+C6)+B7*(1+C7)) -> 175.31365 | I15: c'est une reference
A16: (2023 = 171,70 + 4 ) | C16: (voir onglet budget)
A17: (2025 = 180,5 + 4) | D17: ici on voit que le total dépasse un peu du budget hors capitation | F17: Montant Moyen | G17: =D15/B8 -> 169.67857
D23: =D14-7579 -> 1415.5

Sheet Tranche
A4: Fraction revenu imposable ( pour une part) | B4: Taux d'imposition | C4: Tranche cotisation
A5: Jusque 10225 € | B5: < -5% | C5: 1
A6: de 10226 à 26070 € | B6: de 5 à 10% | C6: 2
A7: de 26 071 à 74 545 € | B7: de 10 à 15% | C7: 3
A8: de 74546 à 160 336 € | B8: de 15 à 20% | C8: 4
A9: Supérieur à 160 336 € | B9: > 20% | C9: 5
A13: simulateur : | B13: https://simulateur-ir-ifi.impots.gouv.fr/calcul_impot/2023/simplifie/index.htm

Sheet Feuil1
A1: Budget 2024 | D1: =SUM(D3:D20) -> 8178.78
A2: Dépenses prévisionnelles | B2: Cout unitaire | C2: quantité | D2: Total
A3: Location | B3: 100 | C3: 20 | D3: =B3*C3 -> 2000
A4: nettoyage | B4: 100 | C4: 3 | D4: =B4*C4 -> 300
A5: Achats | D5: =B5*C5 -> 0
A6: Assurances | B6: 30 | C6: 1 | D6: =B6*C6 -> 30
A7: Frais Convent | B7: 500 | C7: 1 | D7: =B7*C7 -> 500
A8: Solidarité/frais CAALA | B8: =190+25+25+80+80 -> 400 | C8: 1 | D8: =B8*C8 -> 400
A9: Affranchissements | B9: 30 | C9: 1 | D9: =B9*C9 -> 30
A10: Abonnement numérique | B10: 100 | C10: 1 | D10: =B10*C10 -> 100
A11: Frais gestion banque | B11: 9.09 | C11: 12 | D11: =B11*C11 -> 109.08
A12: Dépenses exceptionnelles | D12: 320
A13: Banquet d'ordre | B13: 20 | C13: 27 | D13: =B13*C13 -> 540
A14: initiation taxes | B14: 40 | C14: 4 | D14: =B14*C14 -> 160
A18: Capit | B18: 171.7 | D18: =B21*B18 -> 3605.7
A19: Region cotis | B19: 4 | D19: =B21*B19 -> 84
A20: Nb Affiliés | B20: 6
A21: Nb membres | B21: 21
